Workbook

Sheet column_info_dataentry
A1: Language | B1: Recorder name | C1: Language | D1: Reference no | E1: Study region | F1: Area name | G1: Kingdom | H1: Taxonomic resolution | I1: Taxonomic unit | J1: Taxonomic unit_revised | K1: Ecosystem | L1: Information source | M1: Gradient | N1: Position | O1: Measurement type | P1: Start period | Q1: End period | R1: N years | S1: Number of censuses | T1: Magnitude of shift | U1: Unit of shift | V1: Azimuth of shift | W1: Shift tested | X1: Shift significant | Y1: Data cleaning | Z1: Modelling conducted | AA1: Other effects | AB1: Shift source | AC1: Notes
A2: EN Multiple-choice format Fill-in-the-blank format | B2: Name of the person recording the entry record | C2: Language that the paper was written in: EN/JA | D2: Reference no | E2: Study region: Japan/Region/Prefecture | F2: Specific name of the study area: e.g. island name, national park name. This might be useful for mapping the study locations later on. | G2: Kingdom of target organism: Animal/Plant/Others | H2: The finest level of the taxonomic resolution used: Species-level/Genus-level/Family-level/Order-level. This might be useful because not all studies report at the species-level. | I2: If finest taxonomic resolution is at the species-level, record Latin name of target organism (e.g. Salvelinus leucomaenis). If it is at other levels, record the name of that taxonomic group (e.g. Fabaceae family). | J2: Cross-reference the taxonomic names within the “Taxonomy unit” against authoritative taxonomic lists. Where inappropriate, please amend the name and record the correct designation here. The following databases are recommended: Marine >> World Register of Marine Species Alpine, Forest, Grassland, River >> CheckListBank | K2: Targeted ecosystem: Marine/Freshwater/Forest/Grassland/Alpine/Other (please specify which ecosystem like Other: wetlands) | L2: How were the resurvey data obtained? Authors did the resurvey/GBIF/Citizen science/etc. | M2: Gradient of the measured shift: Elevation/Depth/Latitude/Longitude/Horizontal We can recompute latitude or longitude shift based on the magnitude of horizontal shift and the bearing/azimuth, using trigonometric. | N2: Study sites position: Leading edge/Centroid/Trailing edge/Unknown of the distribution | O2: Observation mesurement: Occurrence/Abundance | P2: AD The year or the time period corresponding to the baseline data used to assess the range position of the target taxa. (e.g., year 1970, time period 1970-1980) | Q2: AD The year or the time period corresponding to the last resurvey from which the authors assessed the range position of the target taxa. (e.g., year 2010, time period 2010-2020) | R2: Number of years The duration in number of years of the period for which the shift is calculated | S2: Number of censuses How many surveys were performed in the study | T2: How large is the shift in numerical value (shown in conjunction with the ”Unit of shift”). Consider the direction of shift (either positive or negative) when recording. Shifting towards higher elevations, poleward, or towards deeper depth in aquatic systems, respectively, is considered positive, and negative otherwise. For instance, 500 m elevational increase should be anotated 500, but a shift of 200 m downslope should be anotated -200. In terms of longitudinal shifts, eastward should be anotated as positive values while westward should be anotated as negative values | U2: The unit of the shift: meter, km, degrees | V2: Azimuth (angle) of shift in degrees (North is 0 or 360, East is 90, South is 180, West is 270). This is rarely reported, but worth recording when authors report only the horizontal shifts, together with the bearing/azymuth/angle without decomposing it into latitudinal and longitudional shifts. | W2: Whether a statistical test was conducted to assess the significance of the shift at the taxonomic unit level? Yes/No | X2: Is the shift significant ? Yes (significant shift)/No (not significant shift)/NA (not analized) | Y2: Authors use the raw data to compute the range shifts without cleaning (No) or use the cleaned data for the range shift computation (Yes): Yes/No | Z2: Authors compute the range shifts from the modelled range positions (Yes) or compute the shift from raw data (No): Yes/No, Examples of model approaches are logistic regression, random forest, etc. | AA2: Potential causes of range shifts other than temperature alone (land use changes/invasive species/pollution/precipitation changes/etc.) | AB2: For each shift recorded, indicate whether it was stated (numerically) in the paper or estimated from figures. If the shift amount was not provided in the paper, calculate it using user-friendly free software. Record the name of the software used in "Note". | AC2: Add any information needed to clarify the data entries in the different fields
A3: JP 選択肢式 記入式 | B3: 記録者名 | C3: 文献が書かれた言語：EN/JA | D3: 文献番号 | E3: 対象地域：日本全域/地方/都道府県 | F3: 具体的な地名：地域名、島名、国立公園名など。いずれ全体で再調査の場所を地図化するときに便利。 | G3: 対象とした生物界：動物/植物/その他 | H3: 使用されている分類学的解像度のうち最も細かいレベル：種レベル/属レベル/科レベル/目レベル。必ずしも種レベルで報告されていないことも考慮するため。 | I3: 種レベルで報告されている場合は対象とした生物の学名（例 Salvelinus leucomaenis）。他のレベルの場合は、その分類群名（例：マメ科）。 | J3: 「Taxonomi unit」内の分類学名を権威ある分類学リストと照合し、不適切な場合、名称を修正し正しい名称をここに記してください。次のデータベースをお勧めします。 Marine >> World Register of Marine Species Alpine, Forest, Grassland, River >> CheckListBank | K3: 対象とした生態系：海洋/河川/森林/草地/高山/その他（具体的にどの生態系か分かるように、その他：湿地、などと書いてください）。 | L3: 再調査データの取得方法。著者が再調査を実施/GBIF/市民科学など | M3: 分布変化を調べた傾度、方向性：標高/深さ/緯度/経度/水平方向 三角法を用いれば、水平方向の変位量と方位角から緯度/経度の変位量を再計算できる | N3: 研究対象地の位置：分布域の前縁/重心/後縁/不明 に位置する | O3: 観測値：在不在/生物量 | P3: 観測開始年または期間（西暦）対象分類群の分布状況を評価するために用いられた基準データに対応する年または期間（例：年なら1970、期間なら1970-1980） | Q3: 観測終了年または期間（西暦）対象分類群の分布状況を評価した最後の再調査に対応する年または期間。（例：年なら2010、期間なら2010-2020） | R3: シフトが計算される期間の長さ（年数） | S3: 調査回数：実施された調査の回数 | T3: 変化の大きさ(Unit of shiftとセットで示す)：数値。記録時には変動方向（正または負）を考慮すること。標高が高い方向、極方向、水系では深部方向への変動は正とみなされ、それ以外は負とする。例えば、標高500mの上昇は500と記録するが、200mの下り斜面への移動は-200と記録する。経度方向の移動では、東方向は正の値、西方向は負の値として記録する | U3: 変化の単位：メートル、キロメートル、度 | V3: 経度方向の変化の方位角（北を0、東90、南180、西270と考える）。めったに報告されていないが、記録しておくといい。 | W3: 分布のシフトが有意であるかを調べる統計解析が行われたか：Yes/No | X3: シフトは有意か？ : No（有意なシフトなし）/Yes（有意なシフト）/No analyses(解析無し) | Y3: 生データを用いて分布域の移動量を計算している か(No)、データクリーニングを実施してから分布域の移動量を計算しているか(Yes)：Yes/No | Z3: モデルを用いて分布位置を評価してから分布の移動量を計算しているか(Yes）、生データから移動量を計算しているか(No)：Yes/No。モデルはlogistic regressionやrandom forestなどのことを指す。 | AA3: 気温以外の潜在的要因（土地利用変化/外来種/汚染/…） | AB3: 記録された各シフトについて、それが論文に数値で記載されていたか(stated)、図から推定されたか(estimated)を明記してください。 論文にシフト量が記載されていない場合は、使いやすい無料ソフトウェアを使用して計算してください。使用したソフトウェアの名前を「注記」欄に記録してください。 | AC3: 各フィールドのデータ入力内容を明確化するために必要な情報を追加してください。
B4: Nana | C4: JA

Sheet column_info_EnJalist
A1: Language | B1: Reference no | C1: group | D1: article_title | E1: abstract | F1: match_finalresult | G1: Recorder name | H1: Match_Target | I1: Right_Ecosystem | J1: Match_Target_final | K1: Data_section | L1: Comments | M1: source_title | N1: publication_year | O1: authors | P1: doi | Q1: doi of accepted paper
A2: EN | B2: Unique ID for each research paper. If you know a paper that fits this review but not on the list, please add them to this list. Use your initials and numbers to create a unique ID for each paper (e.g., E_TS1). Then, extract the data into the "dataentry" sheet. Papers listed in a previous comprehensive review are added to this list as well (i.e., E_ogawa11) | C2: Which ecosystem the paper is about and thus the group that will read the paper: Marine/Freshwater/Forest/Grassland/Alpine In case the ecosystem classification is incorrect, note the right ecosytem in the Right_Ecosystem column. | D2: Title of the paper. | E2: Abstract of the paper. | F2: Result after the first screening process (Title and abstract screening by ChatGPT + Double check for omission error by human based on titles). Papers that were classified as "yes" or "maybe" qualify for the second screening step, and thus are listed here. | G2: who will read the paper in the group | H2: Whether the paper qualifies for full-text screening after reading the title and abstract: Yes/Maybe/No/Duplicated | I2: If the paper is classified in the wrong ecosystem, please note the correct ecosystem here: Marine/Freshwater/Forest/Grassland/Alpine/Other (please specify which ecosystem) | J2: Whether the paper qualifies after full-text screening: Yes/No "Yes" papers are the ones that contain quantitative info on species range shifts, which will be extracted into the "dataentry" sheet. | K2: From which section of the paper was the info extracted? E.g., Text/Fig 1/Table 2 | L2: Any comments. E.g., reasons for/against qualification, duplication/not able to download/etc. | M2: Title of journal, book, etc. | N2: Year of publication. | O2: Name of authors. | P2: DOI of the paper (URL if DOI is not found) | Q2: If the paper was a preprint and the official article is published, please note the DOI of the published paper here. This is to avoid duplication since the published paper can also be in the list. If the paper is published but not in the list, please add it to the list since data extracted from the published paper is more reliable. In case the article is not published, extract data from the preprint.
A3: JP | B3: 各研究論文の固有ID。 本レビューに該当する論文でリストにないものがあれば、このリストに追加してください。各論文に固有IDを付与するため、イニシャルと数字を使用してください（例：E_TS1）。その後、データを「dataentry」シートに抽出してください。 過去の包括的レビューに掲載された論文も本リストに追加します（例：E_ogawa11） | C3: 本論文が対象とする生態系、および論文を読むグループ：海洋／淡水／森林／草原／高山 生態系の分類が誤っている場合は、正しい生態系をRight_Ecosystem欄に記入してください。 | E3: 論文の要旨 | F3: 一次審査後の結果（ChatGPTによるタイトル・抄録審査＋人間によるタイトルに基づく脱落誤りの再確認）。「はい」または「可能性あり」と分類された論文は二次審査対象となり、ここにリストアップされています。 | G3: グループで誰がこの論文を読むのか | H3: タイトルと抄録を読んだ結果、論文が全文スクリーニングの対象となるか：はい／おそらく／いいえ／重複 | J3: 全文スクリーニングした結果、この論文が適格か：はい／いいえ 「はい」と判定された論文は、種の分布域変動に関する定量的な情報を含むものであり、これらは「データ入力」シートに抽出される。 | K3: 情報はどのセクションから抽出しましたか？ 例：本文／図1／表2 | L3: コメント 例：適格性の理由／不適格の理由、重複／ダウンロード不可など。 | M3: 雑誌や書籍のタイトル | N3: 発行年 | O3: 著者名 | P3: 論文のDOI（DOIが見つからない場合はURL） | Q3: 論文がプレプリントであり正式な論文が公開された場合、公開論文のDOIをここに記入してください。公開論文もリストに含まれる可能性があるため、重複を避けるためです。論文が公開されているがリストにない場合は、公開論文から抽出したデータの方が信頼性が高いため、リストに追加してください。論文が公開されていない場合は、プレプリントからデータを抽出してください。

Sheet En-list_editing
A1: Comment when merging & cleaning | B1: Reference no prev | C1: Reference no editing | D1: Reference no | E1: group | F1: article_title | G1: abstract | H1: match_finalresult | I1: Recorder name | J1: Match_Target | K1: Right_Ecosystem | L1: Match_Target_final | M1: Data_section | N1: Comments | O1: source_title | P1: publication_year | Q1: authors | R1: doi | S1: doi of accepted paper
B2: E_TSakiyama1 | C2: =LEFT(B2,1) & TEXT(RIGHT(B2,LEN(B2)-1),"0000") -> E_TSakiyama1 | D2: E_saki1 | E2: alpine | F2: The advancing timberline on Mt. Fuji: natural recovery or climate change? | G2: The alpine timberline on Mt. Fuji (central Japan) is at 2,400–2,500 m above sea level. Over a 21-year period (1978–1999), we tracked changes in this vegetation boundary on a transect at a site impacted by the 1707 volcanic eruption. The timberline advanced rapidly upwards during this time period. Dominant tree species at the timberline (Alnus maximowiczii, Salix reinii, and Larix kaempferi) colonized sites that were initially largely free of vegetation at higher altitudes. Seedlings of L. kaempferi were particularly abundant at the border of advancing vegetation. According to tree age, we found that this was the first canopy species in the colonized areas. L. kaempferi is drought resistant, and this probably contributes to its establishment capability in the high-altitude climate. Most seedlings of Abies veitchii invaded patches of herbs and shrubs. These vegetation patches in the upper kampfzone provide important shelter for seedlings of invading tree species. We predict that the upward advance of the alpine timberline is a recovery process following the volcanic eruption, and that climate change may accelerate this advance. | H2: yes | I2: Sakiyama | J2: yes | K2: Alpine | L2: Yes | M2: Fig. 4 | N2: The study concludes that the advancing timberline is a natural recovery process rather than climate change effects, but this study is included because climate change is discussed to have an accelerating effect in this natural recovery process. | O2: Journal of Plant Research | P2: 2012 | Q2: Sakio & Masuzawa | R2: https://doi.org/10.1007/s10265-011-0465-3
B3: E1 | C3: =LEFT(B3,1) & TEXT(RIGHT(B3,LEN(B3)-1),"0000") -> E0001 | D3: E0001 | E3: alpine | F3: Climate change impact assessment on mountain snow hydrology by water and energy budget-based distributed hydrological model | G3: A water and energy budget-based distributed hydrological model with improved snow physics (WEB-DHM-S) was applied to elucidate the impact of climate change on mountain snow hydrology in the Shubuto River basin, Hokkaido, Japan. The simulated spatial distribution of snow cover was evaluated using the Moderate Resolution Imaging Spectroradiometer (MODIS) 8-day maximum snow-cover extent (MOD10A2) product, which revealed the model's capability for capturing the spatiotemporal variations in snow cover within the study area. Four Atmosphere Ocean General Circulation Models (A0GCMs) were selected and the SRESA1B emission scenario of the Intergovernmental Panel on Climate Change was used to describe climate predictions in the basin. All AOGCMs predict a future decrease in snowmelt contribution to total discharge 11-22% and an average decrease in SWE of 36%, with a shift in peak SWE by 4-14 days. The shift in runoff regime is broadly consistent between the AOGCMs with snowmelt-induced peak discharge expected to occur on average about two weeks earlier in the future hydrological year. The warming climate will drive a shift in runoff regime from a combined rainfall- and snowmelt-driven regime to one with a reduced contribution from snowmelt. The results of the study revealed that the model could be successfully applicable on the basin scale to simulate river discharge and snow processes and to investigate the effect of climate change on hydrological processes. This research contributes to improve the understanding of basin hydrological responses and the pace of change associated with climate variability. (C) 2016 Elsevier B.V. All rights reserved. | H3: yes | I3: Sakiyama | J3: No | N3: The paper is about snow hydrology. | O3: Journal of hydrology | P3: 2016 | Q3: Bhatti, AM; Koike, T; Shrestha, M | R3: 10.1016/j.jhydrol.2016.10.025
B4: E5 | C4: =LEFT(B4,1) & TEXT(RIGHT(B4,LEN(B4)-1),"0000") -> E0005 | D4: E0005 | E4: alpine | F4: Evolutionary history of a cold-adapted limnephilid caddisfly: effects of climate change and topography on genetic structure | G4: The distribution of organisms is influenced by complex factors such as the phylogenetic evolutionary histories of species, the physiological and ecological characteristics of organisms, climate, and geographical and geohistorical features. In this study, we focused on a caddisfly, Asynarchus sachalinensis (Trichoptera: Limnephilidae), which has adapted to cold habitats. From phylogeographic analyses based on the mitochondrial DNA (mtDNA) cytochrome c oxidase subunit I (COI) and 16S rRNA regions and the nuclear DNA (nDNA) 18S rRNA, 28S rRNA, carbamoyl-phosphate synthetase (CAD), elongation factor-1 alpha (EF1-alpha), and RNA polymerase II (POLII) regions, two distinct genetic clades were detected. Clade I was shown to be widely distributed from Sakhalin to Honshu, whereas Clade II was only distributed within Honshu. The distributions of these clades overlapped in Honshu. The habitats were located at relatively lower altitudes for Clade I and higher altitudes for Clade II. The divergence time of these clades was estimated to be during the Pleistocene, indicating that repeated climatic changes facilitated distributional shifts. Haplotype network and demographic analyses based on the mtDNA COI region showed contrasting genetic structures in the two clades. It was indicated that the population sizes of Clade I had expanded rapidly in a recent period, whereas Clade II had maintained stable population sizes. The habitats of Clade II were typically isolated and scattered at high altitudes, resulting in restricted migration and dispersal because of their discontinuous Sky Island habitats. The habitats of Clade I were located at relatively low altitudes, and it was assumed that the populations were continuous, which resulted in a higher frequency of migration and dispersal between populations. Thus, differences in the spatial scale of the adapted habitats of each clade may have resulted in different patterns of population connectivity and fragmentation associated with repeated climatic changes during the Pleistocene. Our study provided new insight into the distributional patterns of cold-adapted aquatic insects in the Japanese Archipelago. Furthermore, the distributional shifts predicted by ecological niche modeling under future climatic change conditions were different for each clade. Therefore, different principles are required in the assessment of each clade to predict temporal changes in their distributions. | H4: yes | I4: Sakiyama | J4: No | N4: The paper is about phylogenetics. | O4: Molecular phylogenetics and evolution | P4: 2024 | Q4: Suzuki, H; Takenaka, M; Tojo, K | R4: 10.1016/j.ympev.2023.107967
B5: E9 | C5: =LEFT(B5,1) & TEXT(RIGHT(B5,LEN(B5)-1),"0000") -> E0009 | D5: E0009 | E5: alpine | F5: Latitudinal shifts in the distribution of exploited fishes in korean waters during the last 30 years: a consequence of climate change | G5: Sea surface temperatures in Korean waters have increased by approximately 1 degrees C during the past 40 years, implying possible range shifts of marine fishes and invertebrates. We analyzed spatially explicit, commercial catch data for 12 major fish species collected from 1984 to 2010 in Korean waters to evaluate and project their range shifts based on climate-driven hydrographic changes simulated by a general circulation model under a climate change scenario. There were significant relationships between the mean latitude of the catch distribution and water temperature for seven of the 12 species examined. Our circulation model projected that temperature stratification in the Korea Strait will disappear by 2030, and our empirical relationships predicted that the ranges of five of the fish species examined will shift poleward by 19-71 km from the 2000s to the 2030s. Compared with studies of demersal fishes in the western North Atlantic and the North Sea, our estimated speeds of shift in mean latitude of fishes were, on average, slower by factors of 2.3 and 5.7, respectively. This suggests that the pattern of range shift of marine species can vary regionally, depending on oceanographic and geomorphologic conditions. International cooperative research among fisheries scientists from countries throughout the region, especially Japan and China, is required to more reliably and comprehensively assess and project the range shifts of fish species. This will provide a scientific basis for the development of fishery policies and their adaptation to climate change in the western North Pacific. | H5: yes | I5: Sakiyama | J5: Maybe | K5: Marine | L5: Yes? | M5: Fig. 4 | N5: The study area is mentioned as Korean waters, but how to decide marine borders? | O5: Reviews in fish biology and fisheries | P5: 2014 | Q5: Jung, S; Pang, IC; Lee, JH; Choi, I; Cha, HK | R5: 10.1007/s11160-013-9310-1
B6: E22 | C6: =LEFT(B6,1) & TEXT(RIGHT(B6,LEN(B6)-1),"0000") -> E0022 | D6: E0022 | E6: alpine | F6: North by north-west: climate change and directions of density shifts in birds | G6: There is increasing evidence that climate change shifts species distributions towards poles and mountain tops. However, most studies are based on presence-absence data, and either abundance or the observation effort has rarely been measured. In addition, hardly any studies have investigated the direction of shifts and factors affecting them. Here, we show using count data on a 1000km south-north gradient in Finland, that between 1970-1989 and 2000-2012, 128 bird species shifted their densities, on average, 37km towards the north north-east. The species-specific directions of the shifts in density were significantly explained by migration behaviour and habitat type. Although the temperatures have also moved on average towards the north north-east (186km), the species-specific directions of the shifts in density and temperature did not correlate due to high variation in density shifts. Findings highlight that climate change is unlikely the only driver of the direction of species density shifts, but species-specific characteristics and human land-use practices are also influencing the direction. Furthermore, the alarming results show that former climatic conditions in the north-west corner of Finland have already moved out of the country. This highlights the need for an international approach in research and conservation actions to mitigate the impacts of climate change. | H6: maybe | I6: Sakiyama | J6: No | N6: The study is conducted in Finland. | O6: Global change biology | P6: 2016 | Q6: Lehikoinen, A; Virkkala, R | R6: 10.1111/gcb.13150
B7: E29 | C7: =LEFT(B7,1) & TEXT(RIGHT(B7,LEN(B7)-1),"0000") -> E0029 | D7: E0029 | E7: alpine | F7: Seasonal dry-down rates and high stress tolerance promote bamboo invasion above and below treeline | G7: How species invasions impact ecosystem structure and function at important ecotones or boundaries is unknown, but may provide insight into the impacts of climate change and the mechanisms underlying community change. The dwarf bamboo, Sasa kurilensis, may be a good system to understand these issues, as the species impacts ecosystem features as it encroaches beyond treeline into alpine systems. We used remote sensing imagery spanning a 35 year period to quantify S. kurilensis expansion patterns across its range, measured growth and stress tolerances of S. kurilensis above and below treeline, and evaluated components of growth to reveal how shifts in light and water limitations influence the ontogeny of height, branching, and leaf production. We show that S. kurilensis more than doubled its abundance across its range, but more than tripled its abundance near and above treeline. Soil dry-down rates were a key driver of invasion above and below treeline, where growth rates decreased with more rapid rates of soil moisture dry-down. We found S. kurilensis responds to competition and climate stress by increasing allocation to belowground structures at high elevations. Further, it invests more carbon in fewer-yet taller and heavier-aboveground structures in low-light, low elevation environments. It appears this species' success is driven by considerable morphological and physiological flexibility, coupled with changes in water balance associated with snowmelt that in each habitat results in sites increasingly hospitable to bamboo. Overall, this study links resource allocation strategies and physiological responses to climate change and provides a mechanistic explanation of invasion success. | H7: maybe | I7: Sakiyama | J7: Maybe | K7: Alpine | L7: Yes | M7: Table 1 | N7: Computing abundance weighted range shift is possible with the data. | O7: Plant ecology | P7: 2016 | Q7: Winkler, DE; Amagai, Y; Huxman, TE; Kaneko, M; Kudo, G | R7: 10.1007/s11258-016-0649-y
B8: E30 | C8: =LEFT(B8,1) & TEXT(RIGHT(B8,LEN(B8)-1),"0000") -> E0030 | D8: E0030 | E8: alpine | F8: Two types of strong local wind captured by simultaneous multiple-site radiosonde soundings across a mountain range | G8: A radiosonde observation method is presented, consisting of simultaneous radiosonde observations at closely spaced multiple sites using balloons with varied buoyancies. This method was employed during a strong wind event (Suzuka-oroshi) on the lee side of the Suzuka mountain range, Japan, to derive the detailed structure of the wind as it crossed the mountains. Batches of six radiosondes were launched simultaneously from a line of four sites, using balloons with three different degrees of buoyancy. The four sites were 13 km apart along a 35-km-long transect roughly aligned with the prevailing wind. The observations documented two flow regimes: a downslope flow perpendicular to the mountain range, similar to a windstorm, and an unexpectedly strong low-level jet flowing parallel to the mountain range. The method was more successful at delineating the first regime than the second. The first regime was well simulated by a numerical experiment, but the second regime was not. The vertical wind associated with the downslope windstorm was inferred from the changing slopes of potential temperature isentropes. Comparison of the balloon ascent rates with these isentropes meanders and the simulated vertical wind showed that fluctuations in balloon ascent rate provide reliable information on the vertical direction of the wind. An analysis of the second regime using a long-term meteorological dataset shows that the onset of the low-level jet is related to the synoptic-scale shift in vorticity from positive to negative in the observation area. This vorticity shift appears to be a useful indicator for the low-level jet regime. | H8: yes | I8: Sakiyama | J8: No | N8: The study is about wind. | O8: Monthly weather review | P8: 2016 | Q8: Komatsu, KK; Tachibana, Y | R8: 10.1175/MWR-D-15-0347.1
B9: E31 | C9: =LEFT(B9,1) & TEXT(RIGHT(B9,LEN(B9)-1),"0000") -> E0031 | D9: E0031 | E9: alpine | F9: Post-glacial east asian origin of the alpine shrub phyllodoce aleutica (ericaceae) in beringia | G9: Aim: The ice-free area around the Bering Land Bridge, Beringia, has been noted as an important refugium of organisms preferring cold environments such as arctic-alpine plants throughout the Pleistocene climate oscillations. Although numerous phylogeographical studies have supported this refugium, recent studies have challenged the idea of a homogeneous refugium in Beringia. We aim to examine a novel scenario of the post-glacial colonization history of an alpine plant Phyllodoce aleutica in Beringia. Location: The Japanese Archipelago, the Kamchatka Peninsula, the Aleutian Islands, Alaska. Method: The range-wide genetic structure of P. aleutica was elucidated by sequencing 13 nuclear loci. The phylogeographical history was inferred using model-based approaches based on coalescent simulations together with the potential distributions predicted by ecological niche modelling. Results: Bayesian clustering and phylogenetic networks revealed that P. aleutica was divided into three geographically structured groups: the main island of the Japanese Archipelago, the northern island of the archipelago (Hokkaido) and Beringia, including eastern Hokkaido. The demographic history underlying the genetic structure and the potential distributions at present and during Last Glacial Maximum suggest that their divergence likely predated the last glacial period. Except for genetic admixture with the sister species Phyllodoce glanduliflora, populations in Alaska exhibited lower genetic diversity than those in East Asia and exclusively shared two widespread genotypes. Approximate Bayesian computation showed that a demographic model postulating post-glacial expansion into Alaska fit better than alternative models. Main conclusions: Our study suggests that P. aleutica in eastern Beringia originated through post-glacial colonization from East Asia, providing novel insight into the biogeographical history of alpine flora in Beringia. | H9: yes | I9: Sakiyama | J9: No | N9: The study is about phylogeography of alpine plants. | O9: Journal of biogeography | P9: 2018 | Q9: Ikeda, H; Yakubov, V; Barkalov, V; Setoguchi, H | R9: 10.1111/jbi.13230
B10: E33 | C10: =LEFT(B10,1) & TEXT(RIGHT(B10,LEN(B10)-1),"0000") -> E0033 | D10: E0033 | E10: alpine | F10: Elevation-related climate trends dominate fungal co-occurrence network structure and the abundance of keystone taxa on mt. Norikura, japan | G10: Soil fungi play an important role in promoting nutrient cycling and maintaining ecosystem stability. Yet, there has been little understanding of how fungal co-occurrence networks differ along elevational climate gradients, a topic of interest to both macroecology and climate change studies. Based on high-throughput sequencing technology, we investigated the trend in co-occurrence network structure of soil fungal communities at 11 elevation levels along a 2300 m elevation gradient on Mt. Norikura, Japan, and identified the keystone taxa in the network, hypothesizing a progressive decline in network connectivity with elevation due to decreased plant diversity and enhanced environmental stress caused by changes in climate and soil characteristics. Our results demonstrated that network-level topological features such as network size, average degree, clustering coefficient, and modularity decreased significantly with increasing elevation, indicating that the fungal OTUs at low elevation were more closely associated and the network structure was more compact at low elevations. This conclusion was verified by the negative correlation between positive cohesion, negative cohesion and elevation. Moreover, the negative/positive cohesion ratio reached its peak value in mid-elevations with moderate environmental stress, indicating that the fungal community structure in mid-elevations was more stable than that at other elevations. We also found that the keystone taxa were more abundant at lower elevations. Furthermore, statistical analysis revealed that against a background of uniform geology, climate may play a dominant role in determining the properties and intensity of soil fungal networks, and significantly affect the abundance distribution of keystone taxa. These findings enhance understanding of the pattern and mechanism of the fungal community co occurrence network along elevation, as well as the responses of microorganisms to climate change on a vertical scale in montane ecosystems. Importance: Exploration of the elevational distribution of microbial networks and their driving factors and mechanisms may provide opportunities for predicting potential impacts of environmental changes, on ecosystem functions and biogeographic patterns at a broad scale. Although many studies have explored patterns of fungal community diversity and composition along various environmental gradients, it is unclear how the topological structure of co-occurrence networks shifts along elevational temperature gradients. In this study, we found that the connectivity of the fungal community decreased with increasing elevation and that climate was the dominant factor regulating co-occurrence patterns, apparently acting indirectly through soil characteristics. Our results also suggest that higher elevations on mountains have fewer keystone taxa than low elevations. These patterns may be related to the decrease of plant diversity and the increase of environmental stress along elevation gradients. (c) 2021 Elsevier B.V. All rights reserved. | H10: maybe | I10: Sakiyama | J10: No | N10: The study is about fungi network structure. | O10: Science of the total environment | P10: 2021 | Q10: Yang, Y; Shi, Y; Kerfahi, D; Ogwu, MC; Wang, JJ; Dong, K; Takahashi, K; Moroenyane, I; Adams, JM | R10: 10.1016/j.scitotenv.2021.149368
B11: E35 | C11: =LEFT(B11,1) & TEXT(RIGHT(B11,LEN(B11)-1),"0000") -> E0035 | D11: E0035 | E11: alpine | F11: Studies on glacial landforms in japan between 1960 and 2010: personal review | G11: Fifty years of studies on glacial landforms in Japan between 1960 and 2010 are reviewed from the personal perspective of a researcher who devoted a major part of his life to these stu dies. The 1960s was a period in which there was a paradigm shift in the history of glacial landform studies in Japan. This resulted from a series of studies by Tomoya Iozawa using aerial photograph interpretation. He was the first researcher to observe and identify all of the glacial landforms in Japan using aerial photographs, and divided them into two groups: the older and more widespread (Yokoo Stage) and the younger and much less widespread (Karasawa Stage). Following his methodology and staging, extensive research was done in the 1970s, and tephrochronological studies revealed that the older and younger stages correspond to MIS 4 and 2 respectively, although MIS 3 glaciation was recognized later in the Hidaka Range, Hokkaido. A researchers union of glacial and periglacial landforms called Kanrei-chikei Danwakai was established in 1972, Proposed and organized by Isozawa and other young students including the author, it stimulated research. In the 1980s, a reconstruction of the mass balance and flows of past glaciers from glacial landforms was attempted by the author and other researchers. This led to the estimation of the Equilibrium Line Altitude (ELA) of former glaciers in Japan. Inventory work and monitoring of perennial snow patches in the Japanese Alps were also begun in the 1980s, and they encouraged studies on the transformation from perennial snow patch to glacier. In addition, the discovery of an ice body at the bottom of Kuranosuke Cirque, Mt. Tateyama, Northern Japanese Alps gave an important hint to estimating the present (topographical) snowline altitude, which could be much lower than the former evaluation determined only from free air temperature. Both the study of perennial snow patches and mapping of the former ELA clarified the importance of precipitation when determining snowline altitude, and the present ELA was estimated at 2970 m just below the peak of Mt. Tateyama (3003 m). Since the 1990s, glacial landform studies became more closely related to global climatic change within the framework of IGBP-PAGES. Glacial fluctuations in Japan in the last glacial period were mainly controlled by monsoon changes and migration of westerlies, which caused a southern migration of the polar frontal zone. Although the glaciers in Japan were small, even in the glacial period, it is now believed that they are an important indicator of climatic changes because they are very sensitive to monsoon and westerly changes. | H11: yes | I11: Sakiyama | J11: No | N11: The study is a review on glacial landforms in Japann\. | O11: Journal of geography-chigaku zasshi | P11: 2012 | Q11: Ono, Y | R11: 10.5026/jgeography.121.187
B12: E36 | C12: =LEFT(B12,1) & TEXT(RIGHT(B12,LEN(B12)-1),"0000") -> E0036 | D12: E0036 | E12: alpine | F12: Genomic shifts, phenotypic clines, and fitness costs associated with cold tolerance in the asian tiger mosquito | G12: Climatic variation is a key driver of genetic differentiation and phenotypic traits evolution, and local adaptation to temperature is expected in widespread species. We investigated phenotypic and genomic changes in the native range of the Asian tiger mosquito, Aedes albopictus. We first refine the phylogeographic structure based on genome-wide regions (1,901 double-digest restriction-site associated DNA single nucleotide polymophisms [ddRAD SNPs]) from 41 populations. We then explore the patterns of cold adaptation using phenotypic traits measured in common garden (wing size and cold tolerance) and genotype-temperature associations at targeted candidate regions (51,706 exon-capture SNPs) from nine populations. We confirm the existence of three evolutionary lineages including clades A (Malaysia, Thailand, Cambodia, and Laos), B (China and Okinawa), and C (South Korea and Japan). We identified temperature-associated differentiation in 15 out of 221 candidate regions but none in ddRAD regions, supporting the role of directional selection in detected genes. These include genes involved in lipid metabolism and a circadian clock gene. Most outlier SNPs are differently fixed between clades A and C, whereas clade B has an intermediate pattern. Females are larger at higher latitude yet produce no more eggs, which might favor the storage of energetic reserves in colder climate. Nondiapausing eggs from temperate populations survive better to cold exposure than those from tropical populations, suggesting they are protected from freezing damages but this cold tolerance has a fitness cost in terms of egg viability. Altogether, our results provide strong evidence for the thermal adaptation of A. albopictus across its wide temperature range. | H12: yes | I12: Sakiyama | J12: No | N12: This is a genetic study. | O12: Molecular biology and evolution | P12: 2022 | Q12: Sherpa, S; Tutagata, J; Gaude, T; Laporte, F; Kasai, S; Ishak, IH; Guo, X; Shin, J; Boyer, S; Marcombe, S; Chareonviriyaphap, T; David, JP; Chen, XG; Zhou, XH; Després, L | R12: 10.1093/molbev/msac104
B13: E39 | C13: =LEFT(B13,1) & TEXT(RIGHT(B13,LEN(B13)-1),"0000") -> E0039 | D13: E0039 | E13: alpine | F13: Molecular phylogeny, biogeography and ecological niche modelling of cardiocrinum (liliaceae): insights into the evolutionary history of endemic genera distributed across the sino-japanese floristic region | G13: Background and Aims The patterns of evolutionary assembly in the Sino-Japanese floristic region (SJFR) remain largely unknown due to a lack of integrative multidimensional studies throughout the region. To address this issue, we elucidated the evolutionary history of Cardiocrinum (Liliaceae), a genus containing four taxa distributed across the SJFR. Methods Fifty-four populations were sampled throughout the geographical range of Cardiocrinum to assess gen-etic structure, analyse phylogenetic relationships and reconstruct ancestral area based on six chloroplast DNA (cpDNA) fragments and three low copy nuclear genes (LCNG). Ecological niche modelling was used to examine the potential range shifts of Cardiocrinum in response to climatic change. Key Results The molecular data showed high genetic similarity in the cpDNA (98.37 %) and LCNG (94.53 %) sequences. The biogeographical analyses revealed that the ancestor of Cardiocrinum diversified during the late Miocene (approx. 7.32 Mya) in Central China. The ancestor of the C. giganteum lineage dispersed westward to the Himalayas and south-west China with the split between C. giganteum and C. giganteum var. yunnanense occurring around 4.11 Mya consistent with the period of orogeny of the Hengduan Mountains. Some populations of the C. cathayanum lineage dispersed eastward to south Japan via the land bridge approx. 4.97 Mya, providing opportu-nities for allopatric speciation of C. cordatum. The predicted suitable habitats of Cardiocrinum have become smaller and more fragmented since the Last Glacial Maximum. Conclusions Our study provides evidence of a biogeographical pattern of dispersal from Central China to the Himalayas in the west and Japan in the east for genera distributed across the SJFR, and highlights that the orogeny of the Hengduan Mountains and fluctuations of the sea level of the East China Sea played important roles in pro-moting species divergence. | H13: yes | I13: Sakiyama | J13: No | N13: This is a genetic study. | O13: Annals of botany | P13: 2017 | Q13: Yang, LQ; Hu, HY; Xie, C; Lai, SP; Yang, M; He, XJ; Zhou, SD | R13: 10.1093/aob/mcw210
B14: E45 | C14: =LEFT(B14,1) & TEXT(RIGHT(B14,LEN(B14)-1),"0000") -> E0045 | D14: E0045 | E14: alpine | F14: Climate change-based models predict range shifts in the distribution of the only asian plethodontid salamander: karsenia koreana | G14: AbstractPopulations see their range fluctuate in relation to environmental variations, including climate change, and their survival is linked to the maintenance of large enough populations and broad enough distributions during these variations. Most amphibian populations are threatened by numerous ecological and anthropogenic variables acting in synergy with climate change. Accumulating basic ecological data such as range enables the development of population and range dynamics, themselves resulting on adequate conservation plans.Karsenia koreanais the only known Asian plethodontic salamander, occurring in a very restricted area only. Based on presence data, we created an ecological model using six bioclimatic factors with low multicollinearity to define the adequate habitat of the species, and we modelled the predicted suitability of the Korean landscape following four Representative Concentration Pathways (RCPs) predicting climate change scenarios based on CO2concentrations in 2050 and 2070. The maximum entropy model for the current distribution produced a landscape suitability considerably wider than the current known distribution. The projected ranges for each RCP indicated marked increases, decreases and shifts in areas with suitable landscapes due to climate change. The lowest RCP prediction resulted in an increase in suitable area, although potentially without connectivity with current populations, while the highest RCP predictions resulted in a decrease. Our results highlight the potential negative impact of climate change, thus requiring updates in conservation plans forK. koreana. The methods used here can be replicated with any land-dwelling species, and our results reflect expected range shifts for most amphibians of the northern hemisphere. | H14: maybe | I14: Sakiyama | J14: No | N14: This study examines the future range shift. | O14: Scientific reports | P14: 2019 | Q14: A Borzée, D Andersen, J Groffen, HT Kim, Y Bae… | R14: 10.1038/s41598-019-48310-1
B15: E46 | C15: =LEFT(B15,1) & TEXT(RIGHT(B15,LEN(B15)-1),"0000") -> E0046 | D15: E0046 | E15: alpine | F15: Distinct phylogeographic structure of the halophyte Suaeda malacosperma (Chenopodiaceae/Amaranthaceae), endemic to Korea–Japan region, influenced by historical range shift dynamics | G15: Wide-ranging changes to the coastline of East Asia during the glacial periods of the Quaternary might have significantly influenced the genetic structure of coastal plants. To verify its historical migration and potential breaks to gene flow, we investigated the genetic structure of the vulnerable halophyte Suaeda malacosperma, whose distribution is restricted to brackish tidal areas of Korea and Japan. Two chloroplast DNA (cpDNA) regions (rpl32-trnL, trnH-psbA) were used for five individuals each from 11 populations. SNP data obtained via multiplexed ISSR genotyping by sequencing (MIG-Seq) were used for 181 individuals from those populations. Ecological niche modeling (ENM) was combined with genetic analyses to compare current and past distributions. The cpDNA sequences and MIG-Seq data revealed largely congruent results indicating that S. malacosperma consists of three genetic clusters: western coast of Korea, southern coast of Korea, and Japan. The patterns produced through structure analysis and cpDNA haplotypes showed that the gene flow occurred at or after the last glaciation from Japan to the southern coast of Korea via the Korea/Tsushima Strait land bridge. Despite the coastal habitat of this species, ocean currents had less influence. Integrating genetic data with past distribution models by ENM provided insight into potential recolonization routes from refugia in each region. Those data suggested that, instead of contemporary gene flow, a historical range shift due to climate change affected the population structure. These results support the need for a conservation strategy and advance our understanding about the historical range dynamics of coastal plants in temperate East Asia. | H15: yes | I15: Sakiyama | J15: No | N15: This is a genetic study. | O15: Plant Systematics and Evolution | P15: 2019 | Q15: JS Park, K Takayama, Y Suyama, BH Choi | R15: 10.1007/s00606-018-1562-8
B16: E52 | C16: =LEFT(B16,1) & TEXT(RIGHT(B16,LEN(B16)-1),"0000") -> E0052 | D16: E0052 | E16: alpine | F16: Seasonal changes in the ratio of congeneric charrs in northern japanese tributaries with different temperature regimes | G16: Background: The species distributions and community compositions of stream shes are often shaped by water temperature. Stream salmonids, for example, show longitudinal gradients or marked community differences between spring-fed vs. non-spring-fed streams, which may be a result of species-speci c temperature preferences, interspeci c competition, or their interaction (i.e., temperature-dependent competition). Despite the widely reported patterns, how such temperature-associated distributions change across seasons remains largely unknown. If temperature is the main driver, the pattern will change across seasons. Alternatively, seasonal patterns will be obscured if other factors, such as species speci c life histories or seasonal aggregation, are important. Here, we investigated the effects of water temperature on the abundance and species ratio of two potentially competing salmonids, southern Asian Dolly Varden Salvelinus curilus and white-spotted charr Salvelinus leucomaenis, in 6 small tributaries with different temperature regimes (i.e., spring-fed and non-spring-fed) across seasons. Results: Across seasons, the southern Asian Dolly Varden dominated in spring-fed tributaries, whereas white-spotted charr dominated in non-spring-fed tributaries. The seasonal variation in the abundance of southern Asian Dolly Varden and species ratio were explained by water temperature uctuation, whereas that of white-spotted charr was not explained by the temperature uctuation. No winter aggregation was observed in any of the tributaries. In addition, only the species ratio in summer was explained by the water temperature, and the water temperature did not fully explain the species ratio. Conclusions: Our results indicated that temperature preference and/or the strength of interspeci c competition may differ across seasons, which is expected to determine the seasonal distribution patterns in spring-fed and non-spring-fed tributaries. This study underscores the importance of considering seasons when evaluating temperature effects on the distribution of stream salmonids. | H16: yes | I16: Sakiyama | J16: No | N16: This study is about fish community ecology. | O16: Preprint | P16: 2023 | Q16: T Yamada, I Koizumi, F Nakamura | R16: 10.21203/rs.3.rs-2465444/v1 | S16: none found
B17: E70 | C17: =LEFT(B17,1) & TEXT(RIGHT(B17,LEN(B17)-1),"0000") -> E0070 | D17: E0070 | E17: alpine | F17: Aquatic species shows asymmetric distribution range shifts in native and non-native areas | G17: IntroductionClimate change is reshaping the geographical distribution of species across the globe. In marine ecosystems, climate change creates novel challenges to an environment impacted by numerous anthropogenic stressors. Forecasting shifts in species distribution, including the expansion of non-indigenous species under climate change scenarios, is a management challenge for today’s world.MethodsWe applied Bayesian Additive Regression Tree (BART) models to investigate the environmental factors modulating the occurrence and habitat preferences of the Atlantic blue crab Callinectes sapidus Rathbun, 1896 in native and non-native areas. With BART models, we also aimed to predict its current and future distributions under two climate change scenarios (RCPs 4.5 and 8.5). BART models were performed using global occurrences of the Atlantic blue crab – recorded from 1830 to 2022 – and several environmental covariates (i.e., water temperature, salinity, current velocity, and rugosity). Model accuracy was assessed with the Area Under the Curve (AUC) and True Skill Statistics (TSS) criteria. Cross-validation experiments were made to balance accuracy prediction and uncertainty model prediction intervals.Results and discussionAUC and TSS values indicated that data validation was successful for the BART model. Water temperature was the most critical variable affecting the presence probability of the Atlantic blue crab. The BART model predicts asymmetric distribution range shifts on both sides of the Atlantic Ocean. The non-native populations will experience broader shifts in their distribution range than in the native range, and the RCP 8.5 scenario model outputs predict a wider distribution range by the end of the century. Overall, we anticipate significant ecological changes in native and non-native areas. The range expansion in native areas is often equivalent to the ecological shifts induced by invasive species, so lessons learned by ecologists and managers in non-native areas will provide actionable insights to managers in native areas. | H17: maybe | I17: Sakiyama | J17: No | N17: This study examines the future range shift. | O17: Frontiers in Marine Science | P17: 2023 | Q17: EFS Costa, J Encarnação, MA Teodósio… | R17: 10.3389/fmars.2023.1158206
B18: E76 | C18: =LEFT(B18,1) & TEXT(RIGHT(B18,LEN(B18)-1),"0000") -> E0076 | D18: E0076 | E18: alpine | F18: Deep phylogeographic breaks in magpie pica pica across the holarctic: concordance with bioacoustics and phenotypes | G18: We examined sequences of the mitochondrial control region in magpies (Pica pica) from the entire distribution range and found deep genetic splits into four major lineages: (1) group West (Europe-Siberia), (2) group East (southern Far East), (3) P. p. mauritanica (North Africa), and (4) P. p. hudsonia (North America). These lineages show a geographic pattern corresponding to known subspecies or subspecies groups. Genetic variation within the widely-distributed group West is low and neutrality tests supported a recent expansion scenario. The haplotypes from Kamchatka, representing a separated sublineage with clear affinity to the European-Siberian group, are almost identical, implying a recent bottleneck. Group East contained two subclades without clear geographic pattern, presumably due to admixing of populations that had diverged in Pleistocene refuges. The homogeneity of the Kyushu population supports historical reports of introduction of the species from Korea. In contrast, the high variation in the recently established Hokkaido population may reflect an ongoing invasion from several populations of the Far Eastern mainland. Bioacoustic data based on chatter call differentiate groups of subspecies and reflect phylogeographic patterns, i.e., mitochondrial lineages. Furthermore, we report the fast spreading of P. p. jankowskii towards the west along the upper Amur River, and a slower shifting of P. p. leucoptera in the opposite direction thus yielding a new contact zone. Overall, our data support a scenario of divergence in geographic isolation, but the ongoing expansion of distribution ranges may lead to major changes in phylogeographic patterns. | H18: yes | I18: Hayashi | J18: No | N18: The study did not evaluate range shift. | O18: Zoological science | P18: 2017 | Q18: AP Kryukov, LN Spiridonova, S Mori, VY Arkhipov… | R18: 10.2108/zs160119
B19: E131 | C19: =LEFT(B19,1) & TEXT(RIGHT(B19,LEN(B19)-1),"0000") -> E0131 | D19: E0131 | E19: alpine | F19: Assessing non-native invasive orthoptera in europe | G19: Orthoptera encompasses 29,000 species. Due to their ability to migrate long-distances through hitchhiking or active dispersal but also due to their wide dietary spectrum, several orthoptera species can pose a phytosanitary threat. Despite information being scarce and contrasting among sources, we compiled literature on non-native Orthoptera species in Europe for this scoping review. We identified 41 relevant species, 35 are non-native (non-native to Europe n = 8, partly native to Europe n = 21, native range unknown/no information available n = 6), two arguably invasive species to Europe due to proven impacts, two are questionable and another two cryptogenic. Of these, 23 species are considered established. The two invasive orthopterans were the Moroccan LocustDociostaurus maroccanusand the Desert LocustSchistocerca gregaria, which are invasive in several European countries. Non-native orthopterans can react very positively to climate warming, resulting in expanding geographical distributions. Furthermore, the number of invasive orthopterans in Europe is likely higher due to a paucity of assessments, increasing introduction rates, and observable impacts on agriculture as well as native species. While e.g., the Migratory LocustLocusta migratoriacauses large-scale damage to crops by forming swarms, the southern oak bush cricketMeconema meridionalehas a negative impact on native species, but neither species is listed as invasive. Besides this, there are other non-native Orthoptera species that could become invasive given increasing reproduction rates due to suitable conditions. Globalization and rising temperatures due to global warming are both increasing introduction rates and concomitantly the availability of suitable locations for reproduction, successful establishments, and finally swarm building. This will increase the probability of damages to agriculture, thus the economy and native biodiversity, eventually endangering human well-being. It is therefore important to monitor and study the invasiveness and impacts of non-native Orthoptera species to develop efficient management or preventive mitigation strategies. | H19: maybe | I19: Hayashi | J19: No | N19: The study is conducted in Europe. | O19: Preprint | P19: 2023 | Q19: AK Kulessa, A Kouba, D Renault, I Soto… | R19: 10.21203/rs.3.rs-2828952/v1 | S19: none found
B20: E136 | C20: =LEFT(B20,1) & TEXT(RIGHT(B20,LEN(B20)-1),"0000") -> E0136 | D20: E0136 | E20: alpine | F20: Conservation biogeography: our place in the world | G20: Conservation biogeography was imagined as a distinct "applied and interdisciplinary science concerned with the conservation of nature" less than two decades ago. This chapter reviews the development of conservation biogeography since its inception a little over one and half decades ago. It aims to, first, provide a brief timeline of progress in the development of this subdiscipline, followed by an overview of the claimed and examined purview of the field. The chapter then briefly examines several highlights emanating from this approach to date, and concludes with a few speculations on how the subdiscipline might continue to develop in productive directions. Conservation biogeography appears to have made progress since 2005 in its attempt to delineate, conceptually and empirically, a portion of the spatial scale within the vast realm of conservation biology that has not always been of a focal concern among biodiversity researchers. | H20: maybe | I20: Hayashi | J20: No | N20: The study did not evaluate range shift. | O20: Biogeography: an integrative approach of the … | P20: 2021 | Q20: BR Riddle | R20: 10.1002/9781119882381.ch13
B21: E153 | C21: =LEFT(B21,1) & TEXT(RIGHT(B21,LEN(B21)-1),"0000") -> E0153 | D21: E0153 | E21: alpine | F21: Priority coral conservation areas under global warming in the amami islands, southern japan | G21: Coral reef ecosystems are highly sensitive to climate change. The Amami Islands in Southern Japan were selected as the study area. It is important to select areas that should be given priority for conservation and subsequently direct resources there. The objective of this study was to identify locations with low bleaching potential against future increases in water temperature, as well as high larval recruitment from other areas and high larval supply capacity to other areas based on connectivity. We simulated the coral bleaching rate and larval connectivity under historical (2000s) and future (RCP2.6 and RCP8.5 in the 2090s) climate conditions using a high-resolution (1/30° × 1/50°) future ocean regional projection dataset. From the model simulation, coral bleaching did not occur in most areas in the 2000s. However, the bleaching frequency would increase significantly under RCP8.5 in the 2090s, and it is projected that mass coral bleaching events will occur in more than half of the years of that decade. Larval dispersion simulation shows that some particles released from the Amami Islands remain in the same area. However, fluctuations in both the sink strength and the source strength among the islands were larger than those within each island, and differences in connectivity between scenarios were not apparent. Grid cells that have a low bleaching rate and high potential for a larval sink and source under each scenario were selected. Since our results can identify priority conservation areas, it is important to conduct conservation and/or adaptation strategies according to the specific characteristics of each island. | H21: yes | I21: Hayashi | J21: No | K21: Marine | N21: The study did not evaluate range shift. | O21: Coral reefs | P21: 2022 | Q21: H Abe, NH Kumagai, H Yamano | R21: 10.1007/s00338-022-02309-9
B22: E156 | C22: =LEFT(B22,1) & TEXT(RIGHT(B22,LEN(B22)-1),"0000") -> E0156 | D22: E0156 | E22: alpine | F22: Assessing the speciation of a cold water species, japanese sand lance ammodytes personatus, in the northwestern pacific by aflp markers | G22: The use of molecular techniques in biodiversity research increasingly results in the recognition of multiple divergent mitochondrial DNA (mtDNA) lineages below the morphospecies level. However, the overlapping distribution of multiple divergent lineages raises the question of whether some of these lineages are in fact cryptic species. Assessing the status of these divergent lineages, delimiting evolutionarily significant units (ESUs), and identifying the dominant evolutionary and ecological drivers are critical components of successful wildlife conservation and management strategies. Amplified fragment length polymorphism (AFLP) markers were applied to characterize the phylogeography pattern of a cold water species, the Japanese sand lance Ammodytes personatus, in warm and cold ocean currents. A total of 211 individuals sampled from 12 populations through the species’ range, including samples from Kuroshio Current, Oyashio Current, Tsushima Current, and Yellow Sea, were analyzed. The Bayesian assignment probability test and Neighbor joining (NJ) analysis divided these populations into two genetically and geographically distinct clades (northern and southern clades) characterized by different sea surface temperatures. The incongruence between nuclear clades and previous mitochondrial lineages suggested that A. personatus is indeed composed of at least two genetically divergent cryptic species. Pleistocene glaciation isolation after secondary contact, local thermal adaptation, and isolation by distance may explain the observed geographic pattern of two cryptic species and genetic structure within clades. | H22: yes | I22: Hayashi | J22: No | K22: Marine | N22: The study did not evaluate range shift. | O22: Animals | P22: 2018 | Q22: Z Han, Z Wang, T Gao, T Yanagimoto, K Iida | R22: 10.3390/ani8120224
